<?xml version="1.0"?>
<robot xmlns:xacro="http://www.ros.org/wiki/xacro" name="rockbreaker_arm">
  <xacro:arg name="gpu" default="true"/>
  <xacro:property name="gpu" value="$(arg gpu)" />
  <xacro:arg name="organize_cloud" default="true"/>
  <xacro:property name="organize_cloud" value="$(arg organize_cloud)" />
  <xacro:property name="M_PI" value="3.1415926535897931" />
  <xacro:property name="damping_value" value="1.0" />
  <xacro:property name="friction_value" value="0.1" />

  <!-- Import all Gazebo-customization elements, including Gazebo colors -->
  <xacro:include filename="$(find rockbreaker_arm_simulator)/rockbreaker_description/urdf/rockbreaker_arm.gazebo"/>
  <xacro:include filename="$(find rockbreaker_arm_simulator)/rockbreaker_arm_gazebo/models/kinect/model.sdf"/>

  <xacro:macro name="box_inertia" params="x y z mass">
    <!-- <inertial>
      <mass value="${mass}" /> -->
      <inertia ixx="${0.0833333 * mass * (y*y + z*z)}" ixy="0.0" ixz="0.0"
               iyy="${0.0833333 * mass * (x*x + z*z)}" iyz="0.0"
               izz="${0.0833333 * mass * (x*x + y*y)}" />
    <!-- </inertial> -->
  </xacro:macro>


  <!-- Base Fija -->
  <link name="world" />

  <!-- Base Link -->
  <joint name="fixed" type="fixed" >
    <parent link="world" />
    <child link="rockbreaker_base" />
     <origin xyz="-3 -3 15.756649" rpy="0 0 1.571"/>
  </joint>

  <!-- Base Fija -->
  <link name="rockbreaker_base" >
    <visual>
      <origin xyz="0 0 0" rpy="0 0 0"/>
      <geometry>
        <mesh filename="package://rockbreaker_arm_simulator/rockbreaker_description/meshes/basefija.dae" scale="1 1 1"/>
      </geometry>
    </visual>
    <collision>
      <origin xyz="0 0 0" rpy="0 0 0"/>
      <geometry>
        <mesh filename="package://rockbreaker_arm_simulator/rockbreaker_description/meshes/basefija.dae" scale="1 1 1"/>
      </geometry>
    </collision>
    <inertial>
      <origin xyz="0 0 0.3"/>
      <mass value="1000"/>
      <xacro:box_inertia x="2.5" y="2.5" z="0.5" mass="1000"/>
     </inertial>
  </link>

  <!-- Base Rotatoria -->
  <link name="rockbreaker_baserotatoria" >
    <visual>
      <origin xyz="0 0 -0.2" rpy="0 0 3.14"/>
      <geometry>
        <mesh filename="package://rockbreaker_arm_simulator/rockbreaker_description/meshes/base_rotatoria.dae" scale="0.1 0.1 0.1"/>
      </geometry>
    </visual> 
    <collision>
      <origin xyz="0 0 -0.2" rpy="0 0 3.14"/>
      <geometry>
        <mesh filename="package://rockbreaker_arm_simulator/rockbreaker_description/meshes/base_rotatoria.dae" scale="0.1 0.1 0.1"/>
      </geometry>
    </collision>
    <inertial>
      <origin xyz="0 0 0.2" rpy="0 0 1.57"/>
      <mass value="400"/>
     <xacro:box_inertia x="1.4" y="1.4" z="1.1" mass="400"/>
     </inertial>
  </link>

  <!-- Brazo A -->
  <link name="brazo_a" > 
    <visual>
      <origin xyz="0 0 -0.2" rpy="0 0.6 1.57"/>
      <geometry>
        <mesh filename="package://rockbreaker_arm_simulator/rockbreaker_description/meshes/BrazoA_rockbreaker.dae" scale="1 1 1"/>
      </geometry>
    </visual>
    <collision>
      <origin xyz="0 0 -0.2" rpy="0 0.6 1.57"/>
      <geometry>
           <mesh filename="package://rockbreaker_arm_simulator/rockbreaker_description/meshes/BrazoA_rockbreaker.dae" scale="1 1 1"/>
      </geometry>
    </collision>
    <inertial>
      <origin xyz="-0.4 -3.0 3.2" rpy="0 0.6 1.57"/>
      <mass value="160"/>
       <xacro:box_inertia x="7.8" y="1.5" z="1.5" mass="100"/>
     </inertial>
  </link>

  <!-- Brazo B -->
  <link name="brazo_b" >
    <visual>
      <origin xyz="0 0 -0.2" rpy="0 0.6 1.57"/>
      <geometry>
        <mesh filename="package://rockbreaker_arm_simulator/rockbreaker_description/meshes/BrazoB_rockbreaker.dae" scale="1 1 1"/>
      </geometry>
    </visual>
    <collision>
      <origin xyz="0 0 -0.2" rpy="0 0.6 1.57"/>
      <geometry>
        <mesh filename="package://rockbreaker_arm_simulator/rockbreaker_description/meshes/BrazoB_rockbreaker.dae" scale="1 1 1"/>
      </geometry>
    </collision>
    <inertial>
      <origin xyz="0.5 -4.0 2.8" rpy="0 0.6 1.57"/>
      <mass value="80"/>
     <xacro:box_inertia x="6.0" y="1" z="1.5" mass="80"/>
     </inertial>
  </link>

    <!-- Hydraulic Hammer -->
  <link name="h_hammer" >
    <visual>
      <origin xyz="0 0 -0.2" rpy="0 1.57 1.57"/>
      <geometry> 
        <mesh filename="package://rockbreaker_arm_simulator/rockbreaker_description/meshes/Hydraulic_Hammer.dae" scale="1 1 1"/>
      </geometry>
    </visual>
    <collision>
      <origin xyz="0 0 -0.2" rpy="0 1.57 1.57"/>
      <geometry>
         <mesh filename="package://rockbreaker_arm_simulator/rockbreaker_description/meshes/Hydraulic_Hammer.dae" scale="1 1 1"/>
      </geometry>
    </collision>
    <inertial>
      <origin xyz="-0.4 -1.5 0.2" rpy="0 1.57 1.57"/>
      <mass value="40"/>
     <xacro:box_inertia x="1.0" y="1.3" z="2." mass="40"/>
     </inertial>
  </link>

  
    <!-- Joints of Rockbreaker Arm -->
  <joint name="joint_base_rockbreaker" type="revolute" >
    <axis xyz="0 0 1"/>
    <limit effort="1000000" lower="-1.57" upper="1.57" velocity="1"/>
    <parent link="rockbreaker_base" />
    <child link="rockbreaker_baserotatoria"  />
    <origin xyz="0 0 1.1 " rpy="0 0 0" />
    <dynamics damping="${damping_value}" friction="${friction_value}"/>
  </joint>

  <joint name="joint_brazoa" type="revolute" >
    <axis xyz="1 0 0"/>
    <limit effort="1000000" lower="-0.4886" upper="0.4014" velocity="1"/>
    <parent link="rockbreaker_baserotatoria" />
    <child link="brazo_a" />
    <origin xyz="0.375 0.05 1.2" rpy="0 0 0" /> 
    <dynamics damping="${damping_value}" friction="${friction_value}"/>
  </joint>

  <joint name="joint_brazob" type="revolute" >
    <axis xyz="1 0 0"/>
    <limit effort="100000" lower="0.7699" upper="2.7053" velocity="1"/>
    <parent link="brazo_a" />
    <child link="brazo_b" />
    <origin xyz="-0.9 -6.75 4.6" rpy="0 0 0" /> 
    <dynamics damping="${damping_value}" friction="${friction_value}"/>
  </joint>

  <joint name="joint_hammer" type="revolute" >
    <axis xyz="1 0 0"/>
    <limit effort="100000" lower="-0.9250" upper="1.6930" velocity="1"/>
    <parent link="brazo_b" />
    <child link="h_hammer" />
    <origin xyz="0.875 -6.82 4.68" rpy="0 0 0" />
    <dynamics damping="${damping_value}" friction="${friction_value}"/> 
  </joint>

  <!-- Transmission of Joints -->

  <transmission name="tran1">
    <type>transmission_interface/SimpleTransmission</type>
    <joint name="joint_base_rockbreaker">
      <hardwareInterface>hardware_interface/PositionJointInterface</hardwareInterface>
    </joint>
    <actuator name="motor1">
      <hardwareInterface>hardware_interface/PositionJointInterface</hardwareInterface>
      <mechanicalReduction>1</mechanicalReduction>
    </actuator>
  </transmission>

  <transmission name="tran2">
    <type>transmission_interface/SimpleTransmission</type>
    <joint name="joint_brazoa">
      <hardwareInterface>hardware_interface/PositionJointInterface</hardwareInterface>
    </joint>
    <actuator name="motor2">
      <hardwareInterface>hardware_interface/PositionJointInterface</hardwareInterface>
      <mechanicalReduction>1</mechanicalReduction>
    </actuator>
  </transmission>

  <transmission name="tran3">
    <type>transmission_interface/SimpleTransmission</type>
    <joint name="joint_brazob">
      <hardwareInterface>hardware_interface/PositionJointInterface</hardwareInterface>
    </joint>
    <actuator name="motor3">
      <hardwareInterface>hardware_interface/PositionJointInterfacee</hardwareInterface>
      <mechanicalReduction>1</mechanicalReduction>
    </actuator>
  </transmission> 

  <transmission name="tran4">
    <type>transmission_interface/SimpleTransmission</type>
    <joint name="joint_hammer">
      <hardwareInterface>hardware_interface/PositionJointInterface</hardwareInterface>
    </joint>
    <actuator name="motor4">
      <hardwareInterface>hardware_interface/PositionJointInterface</hardwareInterface>
      <mechanicalReduction>1</mechanicalReduction>
    </actuator>
  </transmission>

  
  <!-- Lidar OS1-64 #1-->
  <!-- <xacro:include filename="$(find lidar_description)/urdf/OS0-128.urdf.xacro"/>
  <xacro:OS0-128 parent="rockbreaker_base" name="OS0-128" topic="/os0_cloud_node/points" samples="256" >
    <origin xyz="10.85 -12.9 -0.1" rpy="0 0 2.57" />
  </xacro:OS0-128> -->


</robot>
